# An√°lise do Sistema de Follow-up - SDR IA SolarPrime

## üîç Problema Identificado

O sistema de follow-up n√£o est√° funcionando - os follow-ups s√£o criados no banco de dados mas as mensagens nunca s√£o enviadas ap√≥s 30 minutos.

### Log de Exemplo:
```
2025-07-30 04:31:26.784 | INFO | services.follow_up_service:create_follow_up_after_message:91 - 
Follow-up criado para lead 3727426f-aab3-495d-a50b-e28d5e82b1dd - Tipo: first_contact - Agendado para: 02:01 (30 minutos)
```

## üîé An√°lise Detalhada

### 1. **Dois Sistemas de Follow-up Separados**

#### a) `services/follow_up_service.py`
- ‚úÖ Cria registros na tabela `follow_ups` com status 'pending'
- ‚ùå N√ÉO tem nenhum worker/task para processar esses registros
- ‚ùå O m√©todo `get_pending_follow_ups()` existe mas nunca √© chamado
- ‚ùå N√£o tem integra√ß√£o com Celery ou qualquer scheduler

#### b) `services/kommo_follow_up_service.py`
- ‚úÖ Tem tasks do Celery (@celery_app.task)
- ‚úÖ Tem beat schedule configurado (a cada 30 minutos)
- ‚ö†Ô∏è Usa um sistema diferente, n√£o processa os registros da tabela `follow_ups`

### 2. **Follow-up Workflow com AGnO**

#### `workflows/follow_up_workflow.py`
- ‚úÖ Tem um `FollowUpScheduler` completo que processa a tabela `follow_ups`
- ‚úÖ Implementado corretamente com AGnO Workflow
- ‚úÖ Processa follow-ups pendentes e envia mensagens via WhatsApp
- ‚ö†Ô∏è Verifica follow-ups a cada 5 MINUTOS (linha 377)
- ‚ùå S√≥ √© iniciado no `main_v2.py`, n√£o no `main.py`

### 3. **Problemas de Inicializa√ß√£o**

#### `api/main_v2.py` (linha 41)
```python
follow_up_scheduler.start() if config.enable_follow_up else asyncio.sleep(0)
```
- ‚ùå BUG: Usa `config.enable_follow_up` mas deveria ser `agent_config.enable_follow_up`
- ‚ùå Este erro faz com que o scheduler nunca seja iniciado

#### `api/main.py`
- ‚ùå N√£o tem NENHUMA refer√™ncia ao follow_up_scheduler
- ‚ùå Se o servidor estiver usando main.py, o scheduler nunca ser√° iniciado

## üö® Causa Raiz

1. **Se usando `main.py`**: O follow_up_scheduler nunca √© iniciado
2. **Se usando `main_v2.py`**: O scheduler n√£o inicia devido ao bug na linha 41
3. **Resultado**: Os follow-ups s√£o criados no banco mas nunca processados

## ‚úÖ Solu√ß√µes Propostas

### Solu√ß√£o 1: Corrigir o main_v2.py (Recomendada)

```python
# api/main_v2.py linha 41
# ANTES:
follow_up_scheduler.start() if config.enable_follow_up else asyncio.sleep(0)

# DEPOIS:
from config.agent_config import config as agent_config
follow_up_scheduler.start() if agent_config.enable_follow_up else asyncio.sleep(0)
```

### Solu√ß√£o 2: Adicionar ao main.py (Se necess√°rio)

Se o servidor estiver usando `main.py`, adicionar no lifespan:

```python
# api/main.py
from workflows.follow_up_workflow import follow_up_scheduler
from config.agent_config import config as agent_config

# No lifespan, ap√≥s inicializar outros servi√ßos:
if agent_config.enable_follow_up:
    asyncio.create_task(follow_up_scheduler.start())
    logger.info("‚úÖ Follow-up scheduler iniciado")
```

### Solu√ß√£o 3: Reduzir Intervalo de Verifica√ß√£o

No `follow_up_workflow.py` linha 377, mudar de 5 minutos para 1 minuto:

```python
# ANTES:
await asyncio.sleep(300)  # 5 minutos

# DEPOIS:
await asyncio.sleep(60)   # 1 minuto
```

### Solu√ß√£o 4: Alternativa com Celery (Mais complexa)

Adicionar uma task do Celery ao `follow_up_service.py`:

```python
from services.tasks import celery_app
from celery.schedules import crontab

@celery_app.task(name="process_pending_follow_ups")
def process_pending_follow_ups():
    """Processa follow-ups pendentes"""
    import asyncio
    from services.follow_up_service import follow_up_service
    from services.evolution_api import evolution_client
    
    loop = asyncio.get_event_loop()
    pending = loop.run_until_complete(follow_up_service.get_pending_follow_ups())
    
    for follow_up in pending:
        # Enviar mensagem via WhatsApp
        # Marcar como executado
        pass

# Adicionar ao beat schedule
celery_app.conf.beat_schedule.update({
    'process-follow-ups': {
        'task': 'process_pending_follow_ups',
        'schedule': crontab(minute='*'),  # A cada minuto
    }
})
```

## üìã Plano de A√ß√£o

1. **Verificar qual main.py est√° em uso no servidor**
   ```bash
   ps aux | grep uvicorn
   # ou
   docker ps # verificar comando do container
   ```

2. **Aplicar a corre√ß√£o apropriada**:
   - Se `main_v2.py`: Corrigir bug da linha 41
   - Se `main.py`: Adicionar inicializa√ß√£o do scheduler

3. **Reduzir intervalo de verifica√ß√£o** para 1 minuto

4. **Testar**:
   - Verificar logs para confirmar que o scheduler iniciou
   - Criar um follow-up de teste
   - Aguardar 30 minutos e verificar se a mensagem foi enviada

## üîß Configura√ß√µes Relevantes

- `ENABLE_FOLLOW_UP=true` (habilitado por padr√£o)
- `FOLLOW_UP_DELAY_MINUTES=30` (primeiro follow-up ap√≥s 30 minutos)
- `FOLLOW_UP_SECOND_DELAY_HOURS=24` (segundo follow-up ap√≥s 24 horas)

## üìä Resumo

O sistema de follow-up est√° bem implementado mas n√£o est√° sendo executado devido a:
1. Bug de configura√ß√£o no `main_v2.py`
2. Falta de inicializa√ß√£o no `main.py`
3. Intervalo de verifica√ß√£o muito longo (5 minutos)

Com as corre√ß√µes propostas, o sistema funcionar√° corretamente, processando follow-ups a cada minuto e enviando mensagens nos tempos configurados.